Workbook

Sheet Data
A1: TX ID | B1: Product | C1: Quantity | D1: Unit Price | E1: Amount | F1: Order Date | G1: Ship Date | H1: Customer Gender | I1: Order Mode | J1: Rating C | K1: State | L1: County | M1: Days to Deliver | N1: Weeknum | O1: Gender Value
A2: TX500001 | B2: Shorts | C2: 1 | D2: 10.9 | E2: 10.9 | F2: 45658 | G2: 45663 | I2: App | J2: 4 | K2: California | L2: Alpine County | M2: =orders[[#This Row],[Ship Date]]-orders[[#This Row],[Order Date]] -> 5 | N2: =WEEKNUM(orders[[#This Row],[Order Date]]) -> 1 | O2: {=_xlfn.IFS(orders[[#This Row],[Customer Gender]]="M","Male", orders[[#This Row],[Customer Gender]]="F","Female", orders[[#This Row],[Customer Gender]]="O","Other", TRUE,"Unknown")} -> Unknown
A3: TX500002 | B3: Tank Tops | C3: 2 | D3: 30.6 | E3: 61.2 | F3: 45658 | G3: 45660 | H3: M | I3: App | J3: 4 | K3: California | L3: Contra Costa County | M3: =orders[[#This Row],[Ship Date]]-orders[[#This Row],[Order Date]] -> 2 | N3: =WEEKNUM(orders[[#This Row],[Order Date]]) -> 1 | O3: {=_xlfn.IFS(orders[[#This Row],[Customer Gender]]="M","Male", orders[[#This Row],[Customer Gender]]="F","Female", orders[[#This Row],[Customer Gender]]="O","Other", TRUE,"Unknown")} -> Male
A4: TX500003 | B4: Sneakers | C4: 3 | D4: 109.4 | E4: 328.2 | F4: 45658 | G4: 45661 | H4: F | I4: App | J4: 3 | K4: California | L4: Fresno County | M4: =orders[[#This Row],[Ship Date]]-orders[[#This Row],[Order Date]] -> 3 | N4: =WEEKNUM(orders[[#This Row],[Order Date]]) -> 1 | O4: {=_xlfn.IFS(orders[[#This Row],[Customer Gender]]="M","Male", orders[[#This Row],[Customer Gender]]="F","Female", orders[[#This Row],[Customer Gender]]="O","Other", TRUE,"Unknown")} -> Female
A5: TX500004 | B5: Workout Tops | C5: 7 | D5: 37.7 | E5: 263.9 | F5: 45658 | G5: 45659 | H5: F | I5: App | J5: 4 | K5: California | L5: Fresno County | M5: =orders[[#This Row],[Ship Date]]-orders[[#This Row],[Order Date]] -> 1 | N5: =WEEKNUM(orders[[#This Row],[Order Date]]) -> 1 | O5: {=_xlfn.IFS(orders[[#This Row],[Customer Gender]]="M","Male", orders[[#This Row],[Customer Gender]]="F","Female", orders[[#This Row],[Customer Gender]]="O","Other", TRUE,"Unknown")} -> Female
A6: TX500005 | B6: Graphic Tees | C6: 3 | D6: 56.7 | E6: 170.1 | F6: 45658 | G6: 45661 | H6: F | I6: App | J6: 5 | K6: California | L6: Los Angeles County | M6: =orders[[#This Row],[Ship Date]]-orders[[#This Row],[Order Date]] -> 3 | N6: =WEEKNUM(orders[[#This Row],[Order Date]]) -> 1 | O6: {=_xlfn.IFS(orders[[#This Row],[Customer Gender]]="M","Male", orders[[#This Row],[Customer Gender]]="F","Female", orders[[#This Row],[Customer Gender]]="O","Other", TRUE,"Unknown")} -> Female
A7: TX500006 | B7: Tank Tops | C7: 12 | D7: 83.5 | E7: 1002 | F7: 45658 | G7: 45661 | H7: M | I7: Website | J7: 4 | K7: California | L7: Los Angeles County | M7: =orders[[#This Row],[Ship Date]]-orders[[#This Row],[Order Date]] -> 3 | N7: =WEEKNUM(orders[[#This Row],[Order Date]]) -> 1 | O7: {=_xlfn.IFS(orders[[#This Row],[Customer Gender]]="M","Male", orders[[#This Row],[Customer Gender]]="F","Female", orders[[#This Row],[Customer Gender]]="O","Other", TRUE,"Unknown")} -> Male
A8: TX500007 | B8: Sandals | C8: 1 | D8: 55.3 | E8: 55.3 | F8: 45658 | G8: 45659 | H8: F | I8: App | J8: 4 | K8: California | L8: Los Angeles County | M8: =orders[[#This Row],[Ship Date]]-orders[[#This Row],[Order Date]] -> 1 | N8: =WEEKNUM(orders[[#This Row],[Order Date]]) -> 1 | O8: {=_xlfn.IFS(orders[[#This Row],[Customer Gender]]="M","Male", orders[[#This Row],[Customer Gender]]="F","Female", orders[[#This Row],[Customer Gender]]="O","Other", TRUE,"Unknown")} -> Female
A9: TX500008 | B9: Jeans | C9: 2 | D9: 40.3 | E9: 80.6 | F9: 45658 | G9: 45659 | H9: M | I9: Target.com | J9: 5 | K9: California | L9: Los Angeles County | M9: =orders[[#This Row],[Ship Date]]-orders[[#This Row],[Order Date]] -> 1 | N9: =WEEKNUM(orders[[#This Row],[Order Date]]) -> 1 | O9: {=_xlfn.IFS(orders[[#This Row],[Customer Gender]]="M","Male", orders[[#This Row],[Customer Gender]]="F","Female", orders[[#This Row],[Customer Gender]]="O","Other", TRUE,"Unknown")} -> Male
A10: TX500009 | B10: Hoodies & Sweatshirts | C10: 11 | D10: 35.7 | E10: 392.7 | F10: 45658 | G10: 45659 | H10: F | I10: App | J10: 4 | K10: California | L10: Los Angeles County | M10: =orders[[#This Row],[Ship Date]]-orders[[#This Row],[Order Date]] -> 1 | N10: =WEEKNUM(orders[[#This Row],[Order Date]]) -> 1 | O10: {=_xlfn.IFS(orders[[#This Row],[Customer Gender]]="M","Male", orders[[#This Row],[Customer Gender]]="F","Female", orders[[#This Row],[Customer Gender]]="O","Other", TRUE,"Unknown")} -> Female
A11: TX500010 | B11: T-Shirts | C11: 7 | D11: 22.4 | E11: 156.8 | F11: 45658 | G11: 45661 | H11: M | I11: App | J11: 3 | K11: California | L11: Los Angeles County | M11: =orders[[#This Row],[Ship Date]]-orders[[#This Row],[Order Date]] -> 3 | N11: =WEEKNUM(orders[[#This Row],[Order Date]]) -> 1 | O11: {=_xlfn.IFS(orders[[#This Row],[Customer Gender]]="M","Male", orders[[#This Row],[Customer Gender]]="F","Female", orders[[#This Row],[Customer Gender]]="O","Other", TRUE,"Unknown")} -> Male
A12: TX500011 | B12: Sundresses | C12: 2 | D12: 54.4 | E12: 108.8 | F12: 45658 | G12: 45664 | H12: F | I12: App | J12: 4 | K12: California | L12: Los Angeles County | M12: =orders[[#This Row],[Ship Date]]-orders[[#This Row],[Order Date]] -> 6 | N12: =WEEKNUM(orders[[#This Row],[Order Date]]) -> 1 | O12: {=_xlfn.IFS(orders[[#This Row],[Customer Gender]]="M","Male", orders[[#This Row],[Customer Gender]]="F","Female", orders[[#This Row],[Customer Gender]]="O","Other", TRUE,"Unknown")} -> Female
A13: TX500012 | B13: Sundresses | C13: 2 | D13: 49 | E13: 98 | F13: 45658 | G13: 45660 | H13: F | I13: Target.com | J13: 3 | K13: California | L13: Los Angeles County | M13: =orders[[#This Row],[Ship Date]]-orders[[#This Row],[Order Date]] -> 2 | N13: =WEEKNUM(orders[[#This Row],[Order Date]]) -> 1 | O13: {=_xlfn.IFS(orders[[#This Row],[Customer Gender]]="M","Male", orders[[#This Row],[Customer Gender]]="F","Female", orders[[#This Row],[Customer Gender]]="O","Other", TRUE,"Unknown")} -> Female
A14: TX500013 | B14: Sandals | C14: 7 | D14: 118.6 | E14: 830.2 | F14: 45658 | G14: 45662 | H14: F | I14: Website | J14: 4 | K14: California | L14: Nevada County | M14: =orders[[#This Row],[Ship Date]]-orders[[#This Row],[Order Date]] -> 4 | N14: =WEEKNUM(orders[[#This Row],[Order Date]]) -> 1 | O14: {=_xlfn.IFS(orders[[#This Row],[Customer Gender]]="M","Male", orders[[#This Row],[Customer Gender]]="F","Female", orders[[#This Row],[Customer Gender]]="O","Other", TRUE,"Unknown")} -> Female
... A28: TX500027 | B28: Tank Tops | C28: 9 | D28: 38.7 | E28: 348.3 | F28: 45658 | G28: 45661 | H28: M | I28: Website | J28: 4 | K28: California | L28: Santa Barbara County | M28: =orders[[#This Row],[Ship Date]]-orders[[#This Row],[Order Date]] -> 3 | N28: =WEEKNUM(orders[[#This Row],[Order Date]]) -> 1 | O28: {=_xlfn.IFS(orders[[#This Row],[Customer Gender]]="M","Male", orders[[#This Row],[Customer Gender]]="F","Female", orders[[#This Row],[Customer Gender]]="O","Other", TRUE,"Unknown")} -> Male
A29: TX500028 | B29: Tote Bags | C29: 4 | D29: 57.2 | E29: 228.8 | F29: 45658 | G29: 45660 | I29: Website | J29: 5 | K29: California | L29: Santa Clara County | M29: =orders[[#This Row],[Ship Date]]-orders[[#This Row],[Order Date]] -> 2 | N29: =WEEKNUM(orders[[#This Row],[Order Date]]) -> 1 | O29: {=_xlfn.IFS(orders[[#This Row],[Customer Gender]]="M","Male", orders[[#This Row],[Customer Gender]]="F","Female", orders[[#This Row],[Customer Gender]]="O","Other", TRUE,"Unknown")} -> Unknown
A30: TX500029 | B30: Jeans | C30: 5 | D30: 50.9 | E30: 254.5 | F30: 45658 | G30: 45664 | I30: Website | J30: 5 | K30: California | L30: Tehama County | M30: =orders[[#This Row],[Ship Date]]-orders[[#This Row],[Order Date]] -> 6 | N30: =WEEKNUM(orders[[#This Row],[Order Date]]) -> 1 | O30: {=_xlfn.IFS(orders[[#This Row],[Customer Gender]]="M","Male", orders[[#This Row],[Customer Gender]]="F","Female", orders[[#This Row],[Customer Gender]]="O","Other", TRUE,"Unknown")} -> Unknown
A31: TX500030 | B31: Baseball Caps | C31: 7 | D31: 41 | E31: 287 | F31: 45658 | G31: 45662 | H31: F | I31: Website | J31: 4 | K31: California | L31: Ventura County | M31: =orders[[#This Row],[Ship Date]]-orders[[#This Row],[Order Date]] -> 4 | N31: =WEEKNUM(orders[[#This Row],[Order Date]]) -> 1 | O31: {=_xlfn.IFS(orders[[#This Row],[Customer Gender]]="M","Male", orders[[#This Row],[Customer Gender]]="F","Female", orders[[#This Row],[Customer Gender]]="O","Other", TRUE,"Unknown")} -> Female
A32: TX500031 | B32: T-Shirts | C32: 7 | D32: 19.1 | E32: 133.7 | F32: 45658 | G32: 45662 | H32: M | I32: App | J32: 5 | K32: California | L32: Calaveras County | M32: =orders[[#This Row],[Ship Date]]-orders[[#This Row],[Order Date]] -> 4 | N32: =WEEKNUM(orders[[#This Row],[Order Date]]) -> 1 | O32: {=_xlfn.IFS(orders[[#This Row],[Customer Gender]]="M","Male", orders[[#This Row],[Customer Gender]]="F","Female", orders[[#This Row],[Customer Gender]]="O","Other", TRUE,"Unknown")} -> Male
A33: TX500032 | B33: Sneakers | C33: 5 | D33: 166.1 | E33: 830.5 | F33: 45658 | G33: 45661 | H33: M | I33: App | J33: 4 | K33: California | L33: Inyo County | M33: =orders[[#This Row],[Ship Date]]-orders[[#This Row],[Order Date]] -> 3 | N33: =WEEKNUM(orders[[#This Row],[Order Date]]) -> 1 | O33: {=_xlfn.IFS(orders[[#This Row],[Customer Gender]]="M","Male", orders[[#This Row],[Customer Gender]]="F","Female", orders[[#This Row],[Customer Gender]]="O","Other", TRUE,"Unknown")} -> Male
A34: TX500033 | B34: Graphic Tees | C34: 3 | D34: 29.9 | E34: 89.7 | F34: 45658 | G34: 45659 | H34: M | I34: Instagram | J34: 4 | K34: California | L34: Los Angeles County | M34: =orders[[#This Row],[Ship Date]]-orders[[#This Row],[Order Date]] -> 1 | N34: =WEEKNUM(orders[[#This Row],[Order Date]]) -> 1 | O34: {=_xlfn.IFS(orders[[#This Row],[Customer Gender]]="M","Male", orders[[#This Row],[Customer Gender]]="F","Female", orders[[#This Row],[Customer Gender]]="O","Other", TRUE,"Unknown")} -> Male
A35: TX500034 | B35: Bikinis | C35: 6 | D35: 21.7 | E35: 130.2 | F35: 45658 | G35: 45660 | H35: O | I35: Target.com | J35: 5 | K35: California | L35: Los Angeles County | M35: =orders[[#This Row],[Ship Date]]-orders[[#This Row],[Order Date]] -> 2 | N35: =WEEKNUM(orders[[#This Row],[Order Date]]) -> 1 | O35: {=_xlfn.IFS(orders[[#This Row],[Customer Gender]]="M","Male", orders[[#This Row],[Customer Gender]]="F","Female", orders[[#This Row],[Customer Gender]]="O","Other", TRUE,"Unknown")} -> Other
A36: TX500035 | B36: Maxi Dresses | C36: 2 | D36: 32 | E36: 64 | F36: 45658 | G36: 45661 | H36: M | I36: App | J36: 5 | K36: California | L36: Los Angeles County | M36: =orders[[#This Row],[Ship Date]]-orders[[#This Row],[Order Date]] -> 3 | N36: =WEEKNUM(orders[[#This Row],[Order Date]]) -> 1 | O36: {=_xlfn.IFS(orders[[#This Row],[Customer Gender]]="M","Male", orders[[#This Row],[Customer Gender]]="F","Female", orders[[#This Row],[Customer Gender]]="O","Other", TRUE,"Unknown")} -> Male
A37: TX500036 | B37: T-Shirts | C37: 2 | D37: 15.8 | E37: 31.6 | F37: 45658 | G37: 45659 | H37: M | I37: Partner App | J37: 5 | K37: California | L37: Los Angeles County | M37: =orders[[#This Row],[Ship Date]]-orders[[#This Row],[Order Date]] -> 1 | N37: =WEEKNUM(orders[[#This Row],[Order Date]]) -> 1 | O37: {=_xlfn.IFS(orders[[#This Row],[Customer Gender]]="M","Male", orders[[#This Row],[Customer Gender]]="F","Female", orders[[#This Row],[Customer Gender]]="O","Other", TRUE,"Unknown")} -> Male
A38: TX500037 | B38: Sneakers | C38: 17 | D38: 203.1 | E38: 3452.7 | F38: 45658 | G38: 45662 | H38: M | I38: Instagram | J38: 3 | K38: California | L38: Los Angeles County | M38: =orders[[#This Row],[Ship Date]]-orders[[#This Row],[Order Date]] -> 4 | N38: =WEEKNUM(orders[[#This Row],[Order Date]]) -> 1 | O38: {=_xlfn.IFS(orders[[#This Row],[Customer Gender]]="M","Male", orders[[#This Row],[Customer Gender]]="F","Female", orders[[#This Row],[Customer Gender]]="O","Other", TRUE,"Unknown")} -> Male
A39: TX500038 | B39: Hoodies & Sweatshirts | C39: 13 | D39: 39 | E39: 507 | F39: 45658 | G39: 45664 | H39: M | I39: App | J39: 5 | K39: California | L39: Los Angeles County | M39: =orders[[#This Row],[Ship Date]]-orders[[#This Row],[Order Date]] -> 6 | N39: =WEEKNUM(orders[[#This Row],[Order Date]]) -> 1 | O39: {=_xlfn.IFS(orders[[#This Row],[Customer Gender]]="M","Male", orders[[#This Row],[Customer Gender]]="F","Female", orders[[#This Row],[Customer Gender]]="O","Other", TRUE,"Unknown")} -> Male
A40: TX500039 | B40: Bikinis | C40: 1 | D40: 26.5 | E40: 26.5 | F40: 45659 | G40: 45660 | H40: M | I40: Target.com | J40: 4 | K40: California | L40: Los Angeles County | M40: =orders[[#This Row],[Ship Date]]-orders[[#This Row],[Order Date]] -> 1 | N40: =WEEKNUM(orders[[#This Row],[Order Date]]) -> 1 | O40: {=_xlfn.IFS(orders[[#This Row],[Customer Gender]]="M","Male", orders[[#This Row],[Customer Gender]]="F","Female", orders[[#This Row],[Customer Gender]]="O","Other", TRUE,"Unknown")} -> Male
A41: TX500040 | B41: Sandals | C41: 1 | D41: 43.1 | E41: 43.1 | F41: 45659 | G41: 45660 | H41: F | I41: Target.com | J41: 3 | K41: California | L41: Los Angeles County | M41: =orders[[#This Row],[Ship Date]]-orders[[#This Row],[Order Date]] -> 1 | N41: =WEEKNUM(orders[[#This Row],[Order Date]]) -> 1 | O41: {=_xlfn.IFS(orders[[#This Row],[Customer Gender]]="M","Male", orders[[#This Row],[Customer Gender]]="F","Female", orders[[#This Row],[Customer Gender]]="O","Other", TRUE,"Unknown")} -> Female
A42: TX500041 | B42: Tank Tops | C42: 3 | D42: 139 | E42: 417 | F42: 45659 | G42: 45660 | H42: F | I42: Partner App | J42: 5 | K42: California | L42: Los Angeles County | M42: =orders[[#This Row],[Ship Date]]-orders[[#This Row],[Order Date]] -> 1 | N42: =WEEKNUM(orders[[#This Row],[Order Date]]) -> 1 | O42: {=_xlfn.IFS(orders[[#This Row],[Customer Gender]]="M","Male", orders[[#This Row],[Customer Gender]]="F","Female", orders[[#This Row],[Customer Gender]]="O","Other", TRUE,"Unknown")} -> Female
... A91: TX500090 | B91: Sneakers | C91: 1 | D91: 97.7 | E91: 97.7 | F91: 45661 | G91: 45664 | H91: F | I91: Website | J91: 4 | K91: California | L91: Los Angeles County | M91: =orders[[#This Row],[Ship Date]]-orders[[#This Row],[Order Date]] -> 3 | N91: =WEEKNUM(orders[[#This Row],[Order Date]]) -> 1 | O91: {=_xlfn.IFS(orders[[#This Row],[Customer Gender]]="M","Male", orders[[#This Row],[Customer Gender]]="F","Female", orders[[#This Row],[Customer Gender]]="O","Other", TRUE,"Unknown")} -> Female
A92: TX500091 | B92: Sundresses | C92: 5 | D92: 54.7 | E92: 273.5 | F92: 45661 | G92: 45664 | I92: App | J92: 5 | K92: California | L92: Riverside County | M92: =orders[[#This Row],[Ship Date]]-orders[[#This Row],[Order Date]] -> 3 | N92: =WEEKNUM(orders[[#This Row],[Order Date]]) -> 1 | O92: {=_xlfn.IFS(orders[[#This Row],[Customer Gender]]="M","Male", orders[[#This Row],[Customer Gender]]="F","Female", orders[[#This Row],[Customer Gender]]="O","Other", TRUE,"Unknown")} -> Unknown
A93: TX500092 | B93: Sneakers | C93: 6 | D93: 130.5 | E93: 783 | F93: 45661 | G93: 45663 | H93: F | I93: App | J93: 3 | K93: California | L93: Riverside County | M93: =orders[[#This Row],[Ship Date]]-orders[[#This Row],[Order Date]] -> 2 | N93: =WEEKNUM(orders[[#This Row],[Order Date]]) -> 1 | O93: {=_xlfn.IFS(orders[[#This Row],[Customer Gender]]="M","Male", orders[[#This Row],[Customer Gender]]="F","Female", orders[[#This Row],[Customer Gender]]="O","Other", TRUE,"Unknown")} -> Female
A94: TX500093 | B94: Maxi Dresses | C94: 2 | D94: 50.4 | E94: 100.8 | F94: 45661 | G94: 45663 | H94: M | I94: Target.com | J94: 5 | K94: California | L94: Sacramento County | M94: =orders[[#This Row],[Ship Date]]-orders[[#This Row],[Order Date]] -> 2 | N94: =WEEKNUM(orders[[#This Row],[Order Date]]) -> 1 | O94: {=_xlfn.IFS(orders[[#This Row],[Customer Gender]]="M","Male", orders[[#This Row],[Customer Gender]]="F","Female", orders[[#This Row],[Customer Gender]]="O","Other", TRUE,"Unknown")} -> Male
A95: TX500094 | B95: Jeans | C95: 13 | D95: 61.5 | E95: 799.5 | F95: 45661 | G95: 45662 | I95: Instagram | J95: 3 | K95: California | L95: Santa Clara County | M95: =orders[[#This Row],[Ship Date]]-orders[[#This Row],[Order Date]] -> 1 | N95: =WEEKNUM(orders[[#This Row],[Order Date]]) -> 1 | O95: {=_xlfn.IFS(orders[[#This Row],[Customer Gender]]="M","Male", orders[[#This Row],[Customer Gender]]="F","Female", orders[[#This Row],[Customer Gender]]="O","Other", TRUE,"Unknown")} -> Unknown
A96: TX500095 | B96: Sundresses | C96: 4 | D96: 30.1 | E96: 120.4 | F96: 45661 | G96: 45662 | H96: F | I96: App | J96: 5 | K96: California | L96: Alameda County | M96: =orders[[#This Row],[Ship Date]]-orders[[#This Row],[Order Date]] -> 1 | N96: =WEEKNUM(orders[[#This Row],[Order Date]]) -> 1 | O96: {=_xlfn.IFS(orders[[#This Row],[Customer Gender]]="M","Male", orders[[#This Row],[Customer Gender]]="F","Female", orders[[#This Row],[Customer Gender]]="O","Other", TRUE,"Unknown")} -> Female
A97: TX500096 | B97: Sneakers | C97: 5 | D97: 74.8 | E97: 374 | F97: 45661 | G97: 45662 | H97: F | I97: Website | J97: 4 | K97: California | L97: Contra Costa County | M97: =orders[[#This Row],[Ship Date]]-orders[[#This Row],[Order Date]] -> 1 | N97: =WEEKNUM(orders[[#This Row],[Order Date]]) -> 1 | O97: {=_xlfn.IFS(orders[[#This Row],[Customer Gender]]="M","Male", orders[[#This Row],[Customer Gender]]="F","Female", orders[[#This Row],[Customer Gender]]="O","Other", TRUE,"Unknown")} -> Female
A98: TX500097 | B98: Sunglasses | C98: 3 | D98: 64.9 | E98: 194.7 | F98: 45661 | G98: 45668 | H98: M | I98: App | J98: 4 | K98: California | L98: Fresno County | M98: =orders[[#This Row],[Ship Date]]-orders[[#This Row],[Order Date]] -> 7 | N98: =WEEKNUM(orders[[#This Row],[Order Date]]) -> 1 | O98: {=_xlfn.IFS(orders[[#This Row],[Customer Gender]]="M","Male", orders[[#This Row],[Customer Gender]]="F","Female", orders[[#This Row],[Customer Gender]]="O","Other", TRUE,"Unknown")} -> Male
A99: TX500098 | B99: Sundresses | C99: 2 | D99: 50.5 | E99: 101 | F99: 45661 | G99: 45663 | H99: M | I99: Website | J99: 4 | K99: California | L99: Kern County | M99: =orders[[#This Row],[Ship Date]]-orders[[#This Row],[Order Date]] -> 2 | N99: =WEEKNUM(orders[[#This Row],[Order Date]]) -> 1 | O99: {=_xlfn.IFS(orders[[#This Row],[Customer Gender]]="M","Male", orders[[#This Row],[Customer Gender]]="F","Female", orders[[#This Row],[Customer Gender]]="O","Other", TRUE,"Unknown")} -> Male
A100: TX500099 | B100: Maxi Dresses | C100: 7 | D100: 63 | E100: 441 | F100: 45661 | G100: 45664 | H100: M | I100: Instagram | J100: 5 | K100: California | L100: Los Angeles County | M100: =orders[[#This Row],[Ship Date]]-orders[[#This Row],[Order Date]] -> 3 | N100: =WEEKNUM(orders[[#This Row],[Order Date]]) -> 1 | O100: {=_xlfn.IFS(orders[[#This Row],[Customer Gender]]="M","Male", orders[[#This Row],[Customer Gender]]="F","Female", orders[[#This Row],[Customer Gender]]="O","Other", TRUE,"Unknown")} -> Male
A101: TX500100 | B101: Sneakers | C101: 3 | D101: 93.6 | E101: 280.8 | F101: 45661 | G101: 45674 | H101: F | I101: App | J101: 5 | K101: California | L101: Los Angeles County | M101: =orders[[#This Row],[Ship Date]]-orders[[#This Row],[Order Date]] -> 13 | N101: =WEEKNUM(orders[[#This Row],[Order Date]]) -> 1 | O101: {=_xlfn.IFS(orders[[#This Row],[Customer Gender]]="M","Male", orders[[#This Row],[Customer Gender]]="F","Female", orders[[#This Row],[Customer Gender]]="O","Other", TRUE,"Unknown")} -> Female
...

Sheet Pivot
G2: Value For Display
A3: Count of TX ID | B3: Sum of Quantity | C3: Sum of Amount | D3: Average of Rating C | E3: Average of Days to Deliver | G3: Orders | H3: Qty | I3: Amount | J3: Avg Rating | K3: Avg Days
A4: 2400 | B4: 11997 | C4: 649019.8 | D4: 3.9620833 | E4: 2.3425 | G4: =TEXT(A4,"#,##") -> 2,400 | H4: =TEXT(B4,"#,##") -> 11,997 | I4: =TEXT(C4,"$#,##,.0k") -> $649.0k | J4: =TEXT(D4,"0.0") -> 4.0 | K4: =TEXT(E4,"0.0") -> 2.3
A7: Weeknum | B7: Sum of Quantity | C7: Sum of Amount
A8: 1 | B8: 546 | C8: 32413.3
A9: 2 | B9: 905 | C9: 49563
A10: 3 | B10: 796 | C10: 41700.4
A11: 4 | B11: 913 | C11: 46782.6
A12: 5 | B12: 844 | C12: 42676.1
A13: 6 | B13: 1202 | C13: 62910.7
A14: 7 | B14: 935 | C14: 50332.2
A15: 8 | B15: 1128 | C15: 58760.6
A16: 9 | B16: 1007 | C16: 52017.3
A17: 10 | B17: 1128 | C17: 64915.7
A18: 11 | B18: 861 | C18: 45943.8
A19: 12 | B19: 944 | C19: 55077.9
A20: 13 | B20: 788 | C20: 45926.2
A21: Grand Total | B21: 11997 | C21: 649019.8
A24: Sum of Amount | B24: Gender Value
A25: Order Mode | B25: Female | C25: Male | D25: Other | E25: Unknown | F25: Grand Total | I25: =$B$25 -> Female | J25: =$C$25 -> Male | K25: =$D$25 -> Other | L25: =$E$25 -> Unknown
A26: App | B26: 0.18961825 | C26: 0.12262322 | D26: 0.010605378 | E26: 0.030599221 | F26: 0.35344607 | H26: =$A$26 -> App | I26: =$B$26 -> 0.18961825 | J26: =$C$26 -> 0.12262322 | K26: =D26 -> 0.010605378 | L26: =E26 -> 0.030599221
A27: Instagram | B27: 0.050283982 | C27: 0.043060782 | D27: 0.0015320026 | E27: 0.017794989 | F27: 0.11267176 | H27: =$A$27 -> Instagram | I27: =$B$27 -> 0.050283982 | J27: =$C$27 -> 0.043060782 | K27: =D27 -> 0.0015320026 | L27: =E27 -> 0.017794989
A28: Partner App | B28: 0.06349606 | C28: 0.04607163 | D28: 0.0023062471 | E28: 0.0038927934 | F28: 0.11576673 | H28: =$A$28 -> Partner App | I28: =$B$28 -> 0.06349606 | J28: =$C$28 -> 0.04607163 | K28: =D28 -> 0.0023062471 | L28: =E28 -> 0.0038927934
A29: Target.com | B29: 0.096337893 | C29: 0.067920116 | D29: 0.0054979833 | E29: 0.012933041 | F29: 0.18268903 | H29: =$A$29 -> Target.com | I29: =$B$29 -> 0.096337893 | J29: =$C$29 -> 0.067920116 | K29: =D29 -> 0.0054979833 | L29: =E29 -> 0.012933041
A30: Website | B30: 0.12522099 | C30: 0.09149274 | D30: 0.0063042761 | E30: 0.012408404 | F30: 0.23542641 | H30: =$A$30 -> Website | I30: =$B$30 -> 0.12522099 | J30: =$C$30 -> 0.09149274 | K30: =D30 -> 0.0063042761 | L30: =E30 -> 0.012408404
A31: Grand Total | B31: 0.52495717 | C31: 0.37116849 | D31: 0.026245886 | E31: 0.077628448 | F31: 1
A34: Quantity | B34: Count of TX ID | D34: Quantity | E34: Count of TX ID
A35: 1 | B35: 397 | D35: =A35 -> 1 | E35: =B35 -> 397
A36: 2 | B36: 540 | D36: =A36 -> 2 | E36: =B36 -> 540
A37: 3 | B37: 375 | D37: =A37 -> 3 | E37: =B37 -> 375
A38: 4 | B38: 246 | D38: =A38 -> 4 | E38: =B38 -> 246
A39: 5 | B39: 195 | D39: =A39 -> 5 | E39: =B39 -> 195
A40: 6 | B40: 122 | D40: =A40 -> 6 | E40: =B40 -> 122
A41: 7 | B41: 114 | D41: =A41 -> 7 | E41: =B41 -> 114
A42: 8 | B42: 73 | D42: 8 to 15 | E42: =SUM(B42:B49) -> 303
A43: 9 | B43: 52 | D43: 15 + | E43: =SUM(B49:B82) -> 123
A44: 10 | B44: 53
A45: 11 | B45: 37
A46: 12 | B46: 33
A47: 13 | B47: 23
...

Sheet Questions & KPIs
B2: KPIs
B3: Total Orders
B4: Total Quantity
B5: Total Amount
B6: Avg. Rating
B7: Avg. Days to Deliver
B10: Questions
B11: Trend in the last 13 weeks
B12: How our customers like to buy
B13: How many they buy?
B14: Which products are popular?
B15: Overall gender split
... B18: How happy are our customers?

Sheet Dashboard
L3: Female | M3: Male | N3: Other | O3: Unknown
B4: 🛒 Orders | K4: App | L4: 0.18961825 | M4: 0.12262322 | N4: 0.010605378 | O4: 0.030599221
B5: =Pivot!G4 -> 2,400 | K5: Instagram | L5: 0.050283982 | M5: 0.043060782 | N5: 0.0015320026 | O5: 0.017794989
K6: Partner App | L6: 0.06349606 | M6: 0.04607163 | N6: 0.0023062471 | O6: 0.0038927934
K7: Target.com | L7: 0.096337893 | M7: 0.067920116 | N7: 0.0054979833 | O7: 0.012933041
B8: 📦 Quantity | K8: Website | L8: 0.12522099 | M8: 0.09149274 | N8: 0.0063042761 | O8: 0.012408404
B9: =Pivot!H4 -> 11,997
B12: 💰 Amount
B13: =Pivot!I4 -> $649.0k
B16: 🌟 Avg. Rating
B17: =Pivot!J4 -> 4.0
B20: 📅 Avg. Days To Deliver
B21: =Pivot!K4 -> 2.3

Sheet Logo & Colors
H2: Resouces:
B3: Logo
H4: Excel Dashboard Tutorial Video
B5: Color Scheme | H5: Adv. Excel Dashboards Course by Chandoo
C6: #9FBFAD | D6: Accent 1 | H6: You will get the full workbook in the course!
C7: #748C76 | D7: Accent 2
C8: #505947 | D8: Accent 3
C9: #BF7F5A | D9: Accent 4
C10: #BF3939 | D10: Accent 5
C11: #4887E6 | D11: Accent 6
B13: Emojis
B14: 🛒 | C14: Orders
B15: 👕 | C15: Quantity
B16: 💰 | C16: Amount
B17: ⭐ | C17: Rating
B18: 📅 | C18: Days to deliver
B21: Format Codes
B22: #,## | C22: value with thousand's seperator
B23: $#,##,.0k | C23: Amount in thousands with one decimal
B24: 0.0 | C24: Other numbers
